<?xml version="1.0" ?>
<!-- =================================================================================== -->
<!-- |    This document was autogenerated by xacro from ./install/diff_drive/share/diff_drive/ddrive.urdf.xacro | -->
<!-- |    EDITING THIS FILE BY HAND IS NOT RECOMMENDED                                 | -->
<!-- =================================================================================== -->
<robot name="buttercup">
  <gazebo reference="base_link">
    <inertial>
      <mass value="1.14395"/>
      <inertia ixx="0.095329" iyy="0.381317" izz="0.476646"/>
    </inertial>
  </gazebo>
  <gazebo reference="left_wheel">
    <inertial>
      <mass value="1"/>
      <inertia ixx="0.043333" iyy="0.043333" izz="0.08"/>
    </inertial>
  </gazebo>
  <gazebo reference="right_wheel">
    <inertial>
      <mass value="1"/>
      <inertia ixx="0.043333" iyy="0.043333" izz="0.08"/>
    </inertial>
  </gazebo>
  <gazebo reference="top_caster">
    <inertial>
      <mass value="1"/>
      <inertia ixx="0.016" iyy="0.016" izz="0.016"/>
    </inertial>
  </gazebo>
  <gazebo reference="bottom_caster">
    <inertial>
      <mass value="1"/>
      <inertia ixx="0.016" iyy="0.016" izz="0.016"/>
    </inertial>
  </gazebo>
  <gazebo>
    <plugin filename="libgz-sim-diff-drive-system.so" name="gz::sim::systems::DiffDrive">
      <left_joint>left_wheel_base</left_joint>
      <right_joint>right_wheel_base</right_joint>
      <wheel_separation>1.2</wheel_separation>
      <wheel_radius>0.4</wheel_radius>
      <odom_publish_frequency>1</odom_publish_frequency>
      <topic>cmd_vel</topic>
    </plugin>
  </gazebo>
  <gazebo>
    <plugin filename="libgz-sim-joint-state-publisher-system.so" name="gz::sim::systems::JointStatePublisher">
</plugin>
  </gazebo>
  <link name="base_link">
    <visual>
      <geometry>
        <box size="2.0 1.0 0.5"/>
      </geometry>
      <material name="red_mat">
        <color rgba="1.0 0.0 0.0 1.0"/>
      </material>
    </visual>
    <collision>
      <geometry>
        <box size="1.5 1.0 0.25"/>
      </geometry>
      <material name="red_mat">
        <color rgba="1.0 0.0 0.0 1.0"/>
      </material>
    </collision>
  </link>
  <link name="bottom_caster">
    <visual>
      <geometry>
        <sphere radius="0.2"/>
      </geometry>
      <material name="green_mat">
        <color rgba="0 0 1 1"/>
      </material>
    </visual>
    <collision>
      <geometry>
        <sphere radius="0.2"/>
      </geometry>
      <material name="green_mat">
        <color rgba="0 0 1 1"/>
      </material>
    </collision>
  </link>
  <link name="top_caster">
    <visual>
      <geometry>
        <sphere radius="0.2"/>
      </geometry>
      <material name="green_mat">
        <color rgba="0 0 1 1"/>
      </material>
    </visual>
    <collision>
      <geometry>
        <sphere radius="0.2"/>
      </geometry>
      <material name="green_mat">
        <color rgba="0 0 1 1"/>
      </material>
    </collision>
  </link>
  <link name="left_wheel">
    <visual>
      <geometry>
        <cylinder length="0.2" radius="0.4"/>
      </geometry>
      <material name="blue_mat">
        <color rgba="0.0 1.0 0.0 1.0"/>
      </material>
    </visual>
    <collision>
      <geometry>
        <cylinder length="0.2" radius="0.4"/>
      </geometry>
      <material name="blue_mat">
        <color rgba="0.0 1.0 0.0 1.0"/>
      </material>
    </collision>
  </link>
  <link name="right_wheel">
    <visual>
      <geometry>
        <cylinder length="0.2" radius="0.4"/>
      </geometry>
      <material name="blue_mat">
        <color rgba="0.0 1.0 0.0 1.0"/>
      </material>
    </visual>
    <collision>
      <geometry>
        <cylinder length="0.2" radius="0.4"/>
      </geometry>
      <material name="blue_mat">
        <color rgba="0.0 1.0 0.0 1.0"/>
      </material>
    </collision>
  </link>
  <joint name="bottom_caster_wheel" type="continuous">
    <origin rpy="0 0 0" xyz="0.8 0 -0.25"/>
    <parent link="base_link"/>
    <child link="bottom_caster"/>
    <axis xyz="1 1 1"/>
  </joint>
  <joint name="top_caster_wheel" type="continuous">
    <origin rpy="0 0 0" xyz="0.8 0 0.25"/>
    <parent link="base_link"/>
    <child link="top_caster"/>
    <axis xyz="1 1 1"/>
  </joint>
  <joint name="left_wheel_base" type="continuous">
    <origin rpy="-1.57 0 0" xyz="-0.5 0.6 0"/>
    <parent link="base_link"/>
    <child link="left_wheel"/>
    <axis xyz="0 0 1"/>
  </joint>
  <joint name="right_wheel_base" type="continuous">
    <origin rpy="1.57 0 0" xyz="-0.5 -0.6 0"/>
    <parent link="base_link"/>
    <child link="right_wheel"/>
    <axis xyz="0 0 1"/>
  </joint>
</robot>
